# useAuth Hook 状态更新问题分析

## 问题描述
使用 `useAuth` hook 的 `changePassword` 方法时，本地错误状态无法正确更新，但直接使用 `authService.changePassword` 可以正常工作。

## 环境
- React: 18.2.0 (支持自动批处理)
- Zustand: 4.5.7
- 状态管理：全局状态 (Zustand) + 本地状态 (useState)

## 问题分析

### 1. 代码流程

#### useAuth hook 中的 changePassword:
```typescript
changePassword: async (data: ChangePasswordRequest) => {
    try {
        set({ isLoading: true, error: null });  // 步骤 1: 清除全局错误
        await authService.changePassword(data);   // 步骤 2: 调用 API
        set({ isLoading: false, error: null });  // 步骤 3: 成功时更新状态
    } catch (error) {
        const apiError = error as ApiError;
        set({                                     // 步骤 4: 失败时设置全局错误
            isLoading: false,
            error: apiError.detail,
        });
        throw error;                              // 步骤 5: 重新抛出错误
    }
}
```

#### ChangePassword 组件中的处理:
```typescript
try {
    setUpdateError(null);                         // 步骤 A: 清除本地错误
    await changePassword(data);                   // 步骤 B: 调用 hook 方法
} catch (error: any) {
    const errorMessage = error?.detail || ...;
    setUpdateError(errorMessage);                 // 步骤 C: 设置本地错误
}
```

### 2. 执行时序

当密码错误时的执行顺序：
1. 组件: `setUpdateError(null)` - 清除本地错误
2. Hook: `set({ isLoading: true, error: null })` - 清除全局错误
3. Hook: `await authService.changePassword(data)` - API 调用失败
4. Hook: `set({ isLoading: false, error: apiError.detail })` - 设置全局错误
5. Hook: `throw error` - 抛出错误
6. 组件: `catch` 块捕获错误
7. 组件: `setUpdateError(errorMessage)` - 尝试设置本地错误

### 3. 可能的问题原因

#### 3.1 React 18 自动批处理
React 18 会自动批处理状态更新，即使在 Promise 和 setTimeout 中也会批处理。这可能导致：
- 多个 `setState` 调用被合并
- 状态更新的时序与预期不同
- 某些状态更新可能被"丢失"或覆盖

#### 3.2 Zustand 和 React 状态更新的交互
- Zustand 的 `set` 调用和 React 的 `setState` 可能在不同的更新周期中执行
- 两个状态管理系统的更新可能存在竞态条件

#### 3.3 闭包陷阱
在 catch 块中访问的 `updateError` 可能是旧值（闭包中捕获的）

### 4. 为什么直接使用 authService 能工作

直接使用 `authService.changePassword`:
```typescript
try {
    setUpdateError(null);
    await authService.changePassword(data);  // 直接调用，没有额外的状态更新
} catch (error: any) {
    setUpdateError(errorMessage);            // 简单直接的错误处理
}
```

优势：
- 没有中间的 Zustand 状态更新
- 没有多层的 try-catch 嵌套
- 状态更新路径更简单直接
- 避免了潜在的批处理问题

## 解决方案

### 方案 1：使用全局 error 状态（推荐）
```typescript
const { changePassword, error } = useAuth();

// 直接使用全局 error 状态显示错误
{error && <div>{error}</div>}
```

### 方案 2：使用 flushSync 避免批处理
```typescript
import { flushSync } from 'react-dom';

catch (error: any) {
    flushSync(() => {
        setUpdateError(errorMessage);
    });
}
```

### 方案 3：继续使用 authService（当前方案）
直接调用 `authService`，避免状态管理的复杂性。

### 方案 4：修改 hook 不抛出错误
修改 `useAuth` hook，让它返回结果而不是抛出错误：
```typescript
changePassword: async (data) => {
    try {
        // ...
        return { success: true };
    } catch (error) {
        // 不抛出错误，返回错误信息
        return { success: false, error: apiError.detail };
    }
}
```

## 建议

1. **短期**：继续使用 `authService` 直接调用，这是最简单可靠的方案
2. **长期**：考虑统一错误处理策略，要么全部使用全局状态，要么全部使用本地状态
3. **最佳实践**：避免混合使用全局和本地错误状态，选择一种并保持一致